2024-05-30 19:46:27,093 ERROR scheduler Exception in Enqueue Events for Site library.localhost
Traceback (most recent call last):
  File "/home/dancinwhale/frappe-bench/apps/frappe/frappe/utils/scheduler.py", line 87, in enqueue_events_for_site
    if is_scheduler_inactive():
       ^^^^^^^^^^^^^^^^^^^^^^^
  File "/home/dancinwhale/frappe-bench/apps/frappe/frappe/utils/scheduler.py", line 131, in is_scheduler_inactive
    if is_scheduler_disabled(verbose=verbose):
       ^^^^^^^^^^^^^^^^^^^^^^^^^^^^^^^^^^^^^^
  File "/home/dancinwhale/frappe-bench/apps/frappe/frappe/utils/scheduler.py", line 144, in is_scheduler_disabled
    frappe.db.get_single_value("System Settings", "enable_scheduler")
  File "/home/dancinwhale/frappe-bench/apps/frappe/frappe/database/database.py", line 846, in get_single_value
    ).run()
      ^^^^^
  File "/home/dancinwhale/frappe-bench/apps/frappe/frappe/query_builder/utils.py", line 84, in execute_query
    result = frappe.db.sql(query, params, *args, **kwargs)  # nosemgrep
             ^^^^^^^^^^^^^^^^^^^^^^^^^^^^^^^^^^^^^^^^^^^^^
  File "/home/dancinwhale/frappe-bench/apps/frappe/frappe/database/database.py", line 213, in sql
    self.connect()
  File "/home/dancinwhale/frappe-bench/apps/frappe/frappe/database/database.py", line 118, in connect
    self._conn: "MariadbConnection" | "PostgresConnection" = self.get_connection()
                                                             ^^^^^^^^^^^^^^^^^^^^^
  File "/home/dancinwhale/frappe-bench/apps/frappe/frappe/database/mariadb/database.py", line 107, in get_connection
    conn = self._get_connection()
           ^^^^^^^^^^^^^^^^^^^^^^
  File "/home/dancinwhale/frappe-bench/apps/frappe/frappe/database/mariadb/database.py", line 113, in _get_connection
    return self.create_connection()
           ^^^^^^^^^^^^^^^^^^^^^^^^
  File "/home/dancinwhale/frappe-bench/apps/frappe/frappe/database/mariadb/database.py", line 116, in create_connection
    return pymysql.connect(**self.get_connection_settings())
           ^^^^^^^^^^^^^^^^^^^^^^^^^^^^^^^^^^^^^^^^^^^^^^^^^
  File "/home/dancinwhale/frappe-bench/env/lib/python3.12/site-packages/pymysql/connections.py", line 361, in __init__
    self.connect()
  File "/home/dancinwhale/frappe-bench/env/lib/python3.12/site-packages/pymysql/connections.py", line 669, in connect
    self._request_authentication()
  File "/home/dancinwhale/frappe-bench/env/lib/python3.12/site-packages/pymysql/connections.py", line 957, in _request_authentication
    auth_packet = self._read_packet()
                  ^^^^^^^^^^^^^^^^^^^
  File "/home/dancinwhale/frappe-bench/env/lib/python3.12/site-packages/pymysql/connections.py", line 775, in _read_packet
    packet.raise_for_error()
  File "/home/dancinwhale/frappe-bench/env/lib/python3.12/site-packages/pymysql/protocol.py", line 219, in raise_for_error
    err.raise_mysql_exception(self._data)
  File "/home/dancinwhale/frappe-bench/env/lib/python3.12/site-packages/pymysql/err.py", line 150, in raise_mysql_exception
    raise errorclass(errno, errval)
pymysql.err.OperationalError: (1698, "Access denied for user '_22a38581f5b21074'@'localhost'")
